[2024-10-28 09:53:46 +0100] [5693] [INFO] Starting gunicorn 23.0.0
[2024-10-28 09:53:46 +0100] [5693] [INFO] Listening at: http://0.0.0.0:8000 (5693)
[2024-10-28 09:53:46 +0100] [5693] [INFO] Using worker: sync
[2024-10-28 09:53:46 +0100] [5694] [INFO] Booting worker with pid: 5694
[2024-10-28 09:53:46 +0100] [5695] [INFO] Booting worker with pid: 5695
[2024-10-28 09:53:46 +0100] [5694] [ERROR] Exception in worker process
Traceback (most recent call last):
  File "/home/meinna/VCS_Projects/arch_linux_authelia-nginx-authentication-app/server/venv/lib/python3.12/site-packages/gunicorn/arbiter.py", line 608, in spawn_worker
    worker.init_process()
  File "/home/meinna/VCS_Projects/arch_linux_authelia-nginx-authentication-app/server/venv/lib/python3.12/site-packages/gunicorn/workers/base.py", line 135, in init_process
    self.load_wsgi()
  File "/home/meinna/VCS_Projects/arch_linux_authelia-nginx-authentication-app/server/venv/lib/python3.12/site-packages/gunicorn/workers/base.py", line 147, in load_wsgi
    self.wsgi = self.app.wsgi()
                ^^^^^^^^^^^^^^^
  File "/home/meinna/VCS_Projects/arch_linux_authelia-nginx-authentication-app/server/venv/lib/python3.12/site-packages/gunicorn/app/base.py", line 66, in wsgi
    self.callable = self.load()
                    ^^^^^^^^^^^
  File "/home/meinna/VCS_Projects/arch_linux_authelia-nginx-authentication-app/server/venv/lib/python3.12/site-packages/gunicorn/app/wsgiapp.py", line 57, in load
    return self.load_wsgiapp()
           ^^^^^^^^^^^^^^^^^^^
  File "/home/meinna/VCS_Projects/arch_linux_authelia-nginx-authentication-app/server/venv/lib/python3.12/site-packages/gunicorn/app/wsgiapp.py", line 47, in load_wsgiapp
    return util.import_app(self.app_uri)
           ^^^^^^^^^^^^^^^^^^^^^^^^^^^^^
  File "/home/meinna/VCS_Projects/arch_linux_authelia-nginx-authentication-app/server/venv/lib/python3.12/site-packages/gunicorn/util.py", line 370, in import_app
    mod = importlib.import_module(module)
          ^^^^^^^^^^^^^^^^^^^^^^^^^^^^^^^
  File "/usr/lib/python3.12/importlib/__init__.py", line 90, in import_module
    return _bootstrap._gcd_import(name[level:], package, level)
           ^^^^^^^^^^^^^^^^^^^^^^^^^^^^^^^^^^^^^^^^^^^^^^^^^^^^
  File "<frozen importlib._bootstrap>", line 1387, in _gcd_import
  File "<frozen importlib._bootstrap>", line 1360, in _find_and_load
  File "<frozen importlib._bootstrap>", line 1324, in _find_and_load_unlocked
ModuleNotFoundError: No module named 'login'
[2024-10-28 09:53:46 +0100] [5695] [ERROR] Exception in worker process
Traceback (most recent call last):
  File "/home/meinna/VCS_Projects/arch_linux_authelia-nginx-authentication-app/server/venv/lib/python3.12/site-packages/gunicorn/arbiter.py", line 608, in spawn_worker
    worker.init_process()
  File "/home/meinna/VCS_Projects/arch_linux_authelia-nginx-authentication-app/server/venv/lib/python3.12/site-packages/gunicorn/workers/base.py", line 135, in init_process
    self.load_wsgi()
  File "/home/meinna/VCS_Projects/arch_linux_authelia-nginx-authentication-app/server/venv/lib/python3.12/site-packages/gunicorn/workers/base.py", line 147, in load_wsgi
    self.wsgi = self.app.wsgi()
                ^^^^^^^^^^^^^^^
  File "/home/meinna/VCS_Projects/arch_linux_authelia-nginx-authentication-app/server/venv/lib/python3.12/site-packages/gunicorn/app/base.py", line 66, in wsgi
    self.callable = self.load()
                    ^^^^^^^^^^^
  File "/home/meinna/VCS_Projects/arch_linux_authelia-nginx-authentication-app/server/venv/lib/python3.12/site-packages/gunicorn/app/wsgiapp.py", line 57, in load
    return self.load_wsgiapp()
           ^^^^^^^^^^^^^^^^^^^
  File "/home/meinna/VCS_Projects/arch_linux_authelia-nginx-authentication-app/server/venv/lib/python3.12/site-packages/gunicorn/app/wsgiapp.py", line 47, in load_wsgiapp
    return util.import_app(self.app_uri)
           ^^^^^^^^^^^^^^^^^^^^^^^^^^^^^
  File "/home/meinna/VCS_Projects/arch_linux_authelia-nginx-authentication-app/server/venv/lib/python3.12/site-packages/gunicorn/util.py", line 370, in import_app
    mod = importlib.import_module(module)
          ^^^^^^^^^^^^^^^^^^^^^^^^^^^^^^^
  File "/usr/lib/python3.12/importlib/__init__.py", line 90, in import_module
    return _bootstrap._gcd_import(name[level:], package, level)
           ^^^^^^^^^^^^^^^^^^^^^^^^^^^^^^^^^^^^^^^^^^^^^^^^^^^^
  File "<frozen importlib._bootstrap>", line 1387, in _gcd_import
  File "<frozen importlib._bootstrap>", line 1360, in _find_and_load
  File "<frozen importlib._bootstrap>", line 1324, in _find_and_load_unlocked
ModuleNotFoundError: No module named 'login'
[2024-10-28 09:53:46 +0100] [5695] [INFO] Worker exiting (pid: 5695)
[2024-10-28 09:53:46 +0100] [5694] [INFO] Worker exiting (pid: 5694)
[2024-10-28 09:53:46 +0100] [5693] [ERROR] Worker (pid:5694) exited with code 3
[2024-10-28 09:53:46 +0100] [5693] [ERROR] Worker (pid:5695) exited with code 3
[2024-10-28 09:54:10 +0100] [5746] [INFO] Starting gunicorn 23.0.0
[2024-10-28 09:54:10 +0100] [5746] [INFO] Listening at: http://0.0.0.0:8000 (5746)
[2024-10-28 09:54:10 +0100] [5746] [INFO] Using worker: sync
[2024-10-28 09:54:10 +0100] [5747] [INFO] Booting worker with pid: 5747
[2024-10-28 09:54:10 +0100] [5747] [ERROR] Exception in worker process
Traceback (most recent call last):
  File "/home/meinna/VCS_Projects/arch_linux_authelia-nginx-authentication-app/server/venv/lib/python3.12/site-packages/gunicorn/arbiter.py", line 608, in spawn_worker
    worker.init_process()
  File "/home/meinna/VCS_Projects/arch_linux_authelia-nginx-authentication-app/server/venv/lib/python3.12/site-packages/gunicorn/workers/base.py", line 135, in init_process
    self.load_wsgi()
  File "/home/meinna/VCS_Projects/arch_linux_authelia-nginx-authentication-app/server/venv/lib/python3.12/site-packages/gunicorn/workers/base.py", line 147, in load_wsgi
    self.wsgi = self.app.wsgi()
                ^^^^^^^^^^^^^^^
  File "/home/meinna/VCS_Projects/arch_linux_authelia-nginx-authentication-app/server/venv/lib/python3.12/site-packages/gunicorn/app/base.py", line 66, in wsgi
    self.callable = self.load()
                    ^^^^^^^^^^^
  File "/home/meinna/VCS_Projects/arch_linux_authelia-nginx-authentication-app/server/venv/lib/python3.12/site-packages/gunicorn/app/wsgiapp.py", line 57, in load
    return self.load_wsgiapp()
           ^^^^^^^^^^^^^^^^^^^
  File "/home/meinna/VCS_Projects/arch_linux_authelia-nginx-authentication-app/server/venv/lib/python3.12/site-packages/gunicorn/app/wsgiapp.py", line 47, in load_wsgiapp
    return util.import_app(self.app_uri)
           ^^^^^^^^^^^^^^^^^^^^^^^^^^^^^
  File "/home/meinna/VCS_Projects/arch_linux_authelia-nginx-authentication-app/server/venv/lib/python3.12/site-packages/gunicorn/util.py", line 370, in import_app
    mod = importlib.import_module(module)
          ^^^^^^^^^^^^^^^^^^^^^^^^^^^^^^^
  File "/usr/lib/python3.12/importlib/__init__.py", line 90, in import_module
    return _bootstrap._gcd_import(name[level:], package, level)
           ^^^^^^^^^^^^^^^^^^^^^^^^^^^^^^^^^^^^^^^^^^^^^^^^^^^^
  File "<frozen importlib._bootstrap>", line 1387, in _gcd_import
  File "<frozen importlib._bootstrap>", line 1360, in _find_and_load
  File "<frozen importlib._bootstrap>", line 1324, in _find_and_load_unlocked
ModuleNotFoundError: No module named 'login_gunicorn'
[2024-10-28 09:54:10 +0100] [5747] [INFO] Worker exiting (pid: 5747)
[2024-10-28 09:54:10 +0100] [5748] [INFO] Booting worker with pid: 5748
[2024-10-28 09:54:10 +0100] [5748] [ERROR] Exception in worker process
Traceback (most recent call last):
  File "/home/meinna/VCS_Projects/arch_linux_authelia-nginx-authentication-app/server/venv/lib/python3.12/site-packages/gunicorn/arbiter.py", line 608, in spawn_worker
    worker.init_process()
  File "/home/meinna/VCS_Projects/arch_linux_authelia-nginx-authentication-app/server/venv/lib/python3.12/site-packages/gunicorn/workers/base.py", line 135, in init_process
    self.load_wsgi()
  File "/home/meinna/VCS_Projects/arch_linux_authelia-nginx-authentication-app/server/venv/lib/python3.12/site-packages/gunicorn/workers/base.py", line 147, in load_wsgi
    self.wsgi = self.app.wsgi()
                ^^^^^^^^^^^^^^^
  File "/home/meinna/VCS_Projects/arch_linux_authelia-nginx-authentication-app/server/venv/lib/python3.12/site-packages/gunicorn/app/base.py", line 66, in wsgi
    self.callable = self.load()
                    ^^^^^^^^^^^
  File "/home/meinna/VCS_Projects/arch_linux_authelia-nginx-authentication-app/server/venv/lib/python3.12/site-packages/gunicorn/app/wsgiapp.py", line 57, in load
    return self.load_wsgiapp()
           ^^^^^^^^^^^^^^^^^^^
  File "/home/meinna/VCS_Projects/arch_linux_authelia-nginx-authentication-app/server/venv/lib/python3.12/site-packages/gunicorn/app/wsgiapp.py", line 47, in load_wsgiapp
    return util.import_app(self.app_uri)
           ^^^^^^^^^^^^^^^^^^^^^^^^^^^^^
  File "/home/meinna/VCS_Projects/arch_linux_authelia-nginx-authentication-app/server/venv/lib/python3.12/site-packages/gunicorn/util.py", line 370, in import_app
    mod = importlib.import_module(module)
          ^^^^^^^^^^^^^^^^^^^^^^^^^^^^^^^
  File "/usr/lib/python3.12/importlib/__init__.py", line 90, in import_module
    return _bootstrap._gcd_import(name[level:], package, level)
           ^^^^^^^^^^^^^^^^^^^^^^^^^^^^^^^^^^^^^^^^^^^^^^^^^^^^
  File "<frozen importlib._bootstrap>", line 1387, in _gcd_import
  File "<frozen importlib._bootstrap>", line 1360, in _find_and_load
  File "<frozen importlib._bootstrap>", line 1324, in _find_and_load_unlocked
ModuleNotFoundError: No module named 'login_gunicorn'
[2024-10-28 09:54:10 +0100] [5748] [INFO] Worker exiting (pid: 5748)
[2024-10-28 09:54:10 +0100] [5746] [ERROR] Worker (pid:5747) exited with code 3
[2024-10-28 09:54:10 +0100] [5746] [ERROR] Worker (pid:5748) was sent SIGTERM!
[2024-10-28 09:54:10 +0100] [5746] [ERROR] Shutting down: Master
[2024-10-28 09:54:10 +0100] [5746] [ERROR] Reason: Worker failed to boot.
